Workbook

Sheet Caregiver Pipeline
A1: Tuniti Care Hero – Caregiver Training Pipeline
A3: # | B3: Caregiver Name | C3: Intake | D3: Course Start | E3: Available From | F3: Avg Score | G3: Practical Status | H3: Qualified | I3: Matched Name (Billing) | J3: Total Billed (ZAR)
A4: 1 | B4: Akhona Nomonde Mkize | C4: Tranche 1 | D4: 45918 | E4: 45981 | F4: 0.9257 | G4: Completed | H4: Completed 288 Hours | I4: — | J4: 0
A5: 2 | B5: Elly Dhlabo | C5: Tranche 1 | D5: 45918 | E5: 45981 | F5: 0.8486 | G5: Completed | H5: Completed 288 Hours | I5: — | J5: 0
A6: 3 | B6: Jolie Mpunga | C6: Tranche 1 | D6: 45918 | E6: 45981 | F6: 0.63 | G6: Completed | H6: Completed 288 Hours | I6: — | J6: 0
A7: 4 | B7: Jovani Mukuna Tshibingu | C7: Tranche 1 | D7: 45918 | E7: 45981 | F7: 0.96 | G7: Completed | H7: Completed 288 Hours | I7: — | J7: 0
A8: 5 | B8: Mafusi Elizabeth Mofokeng | C8: Tranche 1 | D8: 45918 | E8: 45981 | F8: 0.8571 | G8: Completed | H8: Completed 288 Hours | I8: — | J8: 0
A9: 6 | B9: Minenhle Nkazimulo Fuyane | C9: Tranche 1 | D9: 45918 | E9: 45981 | F9: 0.8571 | G9: Completed | H9: Completed 288 Hours | I9: — | J9: 0
A10: 7 | B10: Miriam Mehlomakulu | C10: Tranche 1 | D10: 45918 | E10: 45981 | F10: 0.5367 | G10: Completed | H10: Completed 288 Hours | I10: — | J10: 0
A11: 8 | B11: Mukuna Mbuyi | C11: Tranche 1 | D11: 45918 | E11: 45981 | F11: 0.6314 | G11: Completed | H11: Completed 288 Hours | I11: — | J11: 0
A12: 9 | B12: Nelly | C12: Tranche 1 | D12: 45918 | E12: 45981 | F12: 0.76 | G12: Relocated | H12: No | I12: — | J12: 0
A13: 10 | B13: Ramogohlo Daphney Aphane | C13: Tranche 1 | D13: 45918 | E13: 45981 | F13: 0.7171 | G13: Completed | H13: Completed 288 Hours | I13: — | J13: 0
A14: 11 | B14: Siphiwe Nelly Ezeadum | C14: Tranche 1 | D14: 45918 | E14: 45981 | F14: 0.5017 | G14: Completed | H14: Completed 288 Hours | I14: — | J14: 0
A15: 12 | B15: Sylvie Lubamba Mbaya | C15: Tranche 1 | D15: 45918 | E15: 45981 | F15: 0.84 | G15: Completed | H15: Completed 288 Hours | I15: — | J15: 0
... A85: 82 | B85: Pusheletso Mashego Mashabela | C85: Tranche 6 | D85: 46035 | E85: 46098 | F85: 0.6273 | G85: Still busy | H85: No | I85: — | J85: 0
A86: 83 | B86: Queen Ramokone Sibanda | C86: Tranche 6 | D86: 46035 | E86: 46098 | G86: Not started | H86: No | I86: — | J86: 0
A87: 84 | B87: Rita Ncube | C87: Tranche 6 | D87: 46035 | E87: 46098 | F87: 0.7689 | G87: Still busy | H87: No | I87: — | J87: 0
A88: 85 | B88: Violet Labvu | C88: Tranche 6 | D88: 46035 | E88: 46098 | F88: 0.9025 | G88: Still busy | H88: No | I88: — | J88: 0
A89: 86 | B89: Bekithemba Mpofu | C89: Tranche 7 | D89: 46036 | E89: 46099 | F89: 0.789 | G89: Not started | H89: No | I89: — | J89: 0
A90: 87 | B90: Blessing Rofhiwa Ndou | C90: Tranche 7 | D90: 46036 | E90: 46099 | F90: 0.5517 | G90: Not started | H90: No | I90: — | J90: 0
A91: 88 | B91: Immaculate Tshegofatso Mataboge | C91: Tranche 7 | D91: 46036 | E91: 46099 | F91: 0.8267 | G91: Not started | H91: No | I91: — | J91: 0
A92: 89 | B92: Josephine Olaide Olaleye | C92: Tranche 7 | D92: 46036 | E92: 46099 | F92: 0.6933 | G92: Not started | H92: No | I92: — | J92: 0
A93: 90 | B93: Lydia James Banda | C93: Tranche 7 | D93: 46036 | E93: 46099 | F93: 0.918 | G93: Not started | H93: No | I93: — | J93: 0
A94: 91 | B94: Margaret Mamatime Dimakatso Aphane | C94: Tranche 7 | D94: 46036 | E94: 46099 | F94: 0.745 | G94: Still busy | H94: No | I94: — | J94: 0
A95: 92 | B95: Mary Komwedzai | C95: Tranche 7 | D95: 46036 | E95: 46099 | F95: 0.5892 | G95: Still busy | H95: No | I95: — | J95: 0
A96: 93 | B96: Octovia Xitsundzuxo Marhanele | C96: Tranche 7 | D96: 46036 | E96: 46099 | F96: 0.861 | G96: Not started | H96: No | I96: — | J96: 0
A97: 94 | B97: Patience Sesi Poto | C97: Tranche 7 | D97: 46036 | E97: 46099 | F97: 0.724 | G97: Still busy | H97: No | I97: — | J97: 0
A98: 95 | B98: Sandra Mhaka | C98: Tranche 7 | D98: 46036 | E98: 46099 | F98: 0.6325 | G98: Still busy | H98: No | I98: — | J98: 0
... A113: 110 | B113: Xolile Fortunate Mabizela | C113: Tranche 8 | D113: 46037 | E113: 46100 | F113: 0.6428 | G113: Not started | H113: No | I113: — | J113: 0
A114: 111 | B114: Juliet Tshakane Lekgothoane | C114: Tranche 9 | D114: 46038 | E114: 46108 | G114: Not started | H114: Pending | I114: — | J114: 0
A115: 112 | B115: Karabo Mabye | C115: Tranche 9 | D115: 46038 | E115: 46108 | G115: Not started | H115: Pending | I115: — | J115: 0
A116: 113 | B116: Leandra Sharlen Emalize Williams | C116: Tranche 9 | D116: 46038 | E116: 46108 | G116: Not started | H116: Pending | I116: — | J116: 0
A117: 114 | B117: Lisa Thembi Phasha | C117: Tranche 9 | D117: 46038 | E117: 46108 | G117: Not started | H117: Pending | I117: — | J117: 0
A118: 115 | B118: Mamohlolo Nkalai | C118: Tranche 9 | D118: 46038 | E118: 46108 | G118: Not started | H118: Pending | I118: — | J118: 0
A119: 116 | B119: Marlise Louise Els | C119: Tranche 9 | D119: 46038 | E119: 46108 | G119: Not started | H119: Pending | I119: — | J119: 0
A120: 117 | B120: Mashudu Thalitha Managa | C120: Tranche 9 | D120: 46038 | E120: 46108 | G120: Not started | H120: Pending | I120: — | J120: 0
A121: 118 | B121: Philadelpia Tsakani Mashaba | C121: Tranche 9 | D121: 46038 | E121: 46108 | G121: Not started | H121: Pending | I121: — | J121: 0
A122: 119 | B122: Prisca Ndlovu | C122: Tranche 9 | D122: 46038 | E122: 46108 | G122: Not started | H122: Pending | I122: — | J122: 0
A123: 120 | B123: Reshoketswe Amber Makgahlela | C123: Tranche 9 | D123: 46038 | E123: 46108 | G123: Not started | H123: Pending | I123: — | J123: 0
A124: 121 | B124: Sinqobile Chiropa | C124: Tranche 9 | D124: 46038 | E124: 46108 | G124: Not started | H124: Pending | I124: Thalitha Managa | J124: 2000
...

Sheet Client Summary
A1: TCH Holdings – Client Income Summary (ZAR)
A3: Client | B3: Nov 2025 | C3: Dec 2025 | D3: Jan 2026 | E3: Feb 2026 | F3: Mar 2026 | G3: Apr 2026 | H3: Total
A4: Johnstons | B4: 24000 | C4: 24800 | D4: 23250 | E4: 21000 | F4: 24800 | G4: 16500 | H4: =SUM(B4:G4)
A5: Van Der Linde | B5: 22200 | C5: 22200 | D5: 22200 | E5: 22200 | F5: 22200 | G5: 0 | H5: =SUM(B5:G5)
A6: Hennie | B6: 18600 | C6: 4650 | D6: 0 | E6: 0 | F6: 0 | G6: 0 | H6: =SUM(B6:G6)
A7: John Bierman | B7: 16000 | C7: 18400 | D7: 17600 | E7: 16000 | F7: 17000 | G7: 17600 | H7: =SUM(B7:G7)
A8: Hillery | B8: 3800 | C8: 2850 | D8: 0 | E8: 0 | F8: 0 | G8: 0 | H8: =SUM(B8:G8)
A9: Van Vuuren | B9: 23200 | C9: 0 | D9: 0 | E9: 0 | F9: 0 | G9: 0 | H9: =SUM(B9:G9)
A10: Trevor Botes | B10: 15000 | C10: 16500 | D10: 14250 | E10: 13500 | F10: 17250 | G10: 16500 | H10: =SUM(B10:G10)
A11: Johann Roos | B11: 14000 | C11: 11900 | D11: 0 | E11: 0 | F11: 0 | G11: 0 | H11: =SUM(B11:G11)
A12: Ishaan/Elizabth | B12: 13300 | C12: 0 | D12: 0 | E12: 0 | F12: 0 | G12: 0 | H12: =SUM(B12:G12)
A13: Androilla/ Praxia | B13: 21000 | C13: 7500 | D13: 0 | E13: 0 | F13: 0 | G13: 0 | H13: =SUM(B13:G13)
A14: Jacomina/Charl | B14: 3800 | C14: 0 | D14: 0 | E14: 0 | F14: 0 | G14: 0 | H14: =SUM(B14:G14)
A15: Herman/Rene | B15: 4250 | C15: 0 | D15: 0 | E15: 0 | F15: 0 | G15: 0 | H15: =SUM(B15:G15)
... A56: Anton Steyn/ Emce | B56: 0 | C56: 0 | D56: 0 | E56: 0 | F56: 0 | G56: 3800 | H56: =SUM(B56:G56)
A57: TOTAL | B57: =SUM(B4:B56) | C57: =SUM(C4:C56) | D57: =SUM(D4:D56) | E57: =SUM(E4:E56) | F57: =SUM(F4:F56) | G57: =SUM(G4:G56) | H57: =SUM(H4:H56)
A58: Sheet Total (validation) | B58: 201150 | C58: 223287 | D58: 242994 | E58: 274922 | F58: 370000 | G58: 261200

Sheet Caregiver Summary
A1: TCH Holdings – Caregiver Pay Summary (ZAR)
A3: Caregiver | B3: Nov 2025 | C3: Dec 2025 | D3: Jan 2026 | E3: Feb 2026 | F3: Mar 2026 | G3: Apr 2026 | H3: Total
A4: Linda Rapuluchukwa | B4: 9600 | C4: 9600 | D4: 9600 | E4: 11400 | F4: 10500 | G4: 0 | H4: =SUM(B4:G4)
A5: Sophie Koga | B5: 11250 | C5: 9450 | D5: 10800 | E5: 7450 | F5: 1650 | G5: 0 | H5: =SUM(B5:G5)
A6: Joyce Mutambiranwa | B6: 3150 | C6: 6750 | D6: 10000 | E6: 8900 | F6: 8000 | G6: 0 | H6: =SUM(B6:G6)
A7: Emily Mentula | B7: 3600 | C7: 9450 | D7: 8360 | E7: 7200 | F7: 9450 | G7: 0 | H7: =SUM(B7:G7)
A8: Cynthia Makondo | B8: 8750 | C8: 4200 | D8: 3050 | E8: 7150 | F8: 7650 | G8: 0 | H8: =SUM(B8:G8)
A9: Ruth Nnadi | B9: 0 | C9: 6750 | D9: 7200 | E9: 4950 | F9: 7100 | G9: 0 | H9: =SUM(B9:G9)
A10: Christina Maluleka | B10: 9000 | C10: 9450 | D10: 9450 | E10: 9000 | F10: 12150 | G10: 0 | H10: =SUM(B10:G10)
A11: Mzee Mzwakhe | B11: 6450 | C11: 9400 | D11: 0 | E11: 0 | F11: 0 | G11: 0 | H11: =SUM(B11:G11)
A12: Susan Murire | B12: 5850 | C12: 0 | D12: 7425 | E12: 9000 | F12: 9900 | G12: 0 | H12: =SUM(B12:G12)
A13: Ndai Mapenyenye | B13: 0 | C13: 0 | D13: 0 | E13: 3150 | F13: 8000 | G13: 0 | H13: =SUM(B13:G13)
A14: Adaobi Ejikeme | B14: 6300 | C14: 6750 | D14: 3600 | E14: 6650 | F14: 7300 | G14: 0 | H14: =SUM(B14:G14)
A15: Merriam Maluleke | B15: 4500 | C15: 3340 | D15: 4924 | E15: 2700 | F15: 8000 | G15: 0 | H15: =SUM(B15:G15)
... A45: Annie Mabuto | B45: 0 | C45: 0 | D45: 0 | E45: 0 | F45: 2650 | G45: 0 | H45: =SUM(B45:G45)
A46: TOTAL | B46: =SUM(B4:B45) | C46: =SUM(C4:C45) | D46: =SUM(D4:D45) | E46: =SUM(E4:E45) | F46: =SUM(F4:F45) | G46: =SUM(G4:G45) | H46: =SUM(H4:H45)

Sheet Margin Summary
A1: TCH Holdings – Gross Margin Summary (ZAR)
A3: CONSOLIDATED P&L
B5: Nov 2025 | C5: Dec 2025 | D5: Jan 2026 | E5: Feb 2026 | F5: Mar 2026 | G5: Apr 2026 | H5: Total
A6: Total Client Revenue | B6: ='Client Summary'!B57 | C6: ='Client Summary'!C57 | D6: ='Client Summary'!D57 | E6: ='Client Summary'!E57 | F6: ='Client Summary'!F57 | G6: ='Client Summary'!G57 | H6: ='Client Summary'!H57
A7: Total Caregiver Cost | B7: ='Caregiver Summary'!B46 | C7: ='Caregiver Summary'!C46 | D7: ='Caregiver Summary'!D46 | E7: ='Caregiver Summary'!E46 | F7: ='Caregiver Summary'!F46 | G7: ='Caregiver Summary'!G46 | H7: ='Caregiver Summary'!H46
A8: Gross Margin | B8: =B6-B7 | C8: =C6-C7 | D8: =D6-D7 | E8: =E6-E7 | F8: =F6-F7 | G8: =G6-G7 | H8: =H6-H7
A9: Gross Margin % | B9: =IF(B6=0,0,B8/B6) | C9: =IF(C6=0,0,C8/C6) | D9: =IF(D6=0,0,D8/D6) | E9: =IF(E6=0,0,E8/E6) | F9: =IF(F6=0,0,F8/F6) | G9: =IF(G6=0,0,G8/G6) | H9: =IF(H6=0,0,H8/H6)
A11: Note: Apr 2026 caregiver sheet is empty — margin for Apr reflects revenue only.
A13: PER-CLIENT MARGIN (Nov–Dec 2025, where expense data available)
A15: Client | B15: Income | C15: Expense | D15: Margin | E15: Margin % | F15: Month | G15: Source Sheet
A16: Johnstons | B16: 24000 | C16: 19400 | D16: 4600 | E16: 0.19166667 | F16: Nov 2025 | G16: Clients Nov 2025
A17: Van Der Linde | B17: 22200 | C17: 14441 | D17: 7759 | E17: 0.3495045 | F17: Nov 2025 | G17: Clients Nov 2025
A18: Hennie | B18: 18600 | C18: 13471 | D18: 5129 | E18: 0.27575269 | F18: Nov 2025 | G18: Clients Nov 2025
A19: John Bierman | B19: 16000 | C19: 6450 | D19: 9550 | E19: 0.596875 | F19: Nov 2025 | G19: Clients Nov 2025
A20: Hillery | B20: 3800 | C20: 2250 | D20: 1550 | E20: 0.40789474 | F20: Nov 2025 | G20: Clients Nov 2025
A21: Van Vuuren | B21: 23200 | C21: 10800 | D21: 12400 | E21: 0.53448276 | F21: Nov 2025 | G21: Clients Nov 2025
A22: Trevor Botes | B22: 15000 | C22: 8450 | D22: 6550 | E22: 0.43666667 | F22: Nov 2025 | G22: Clients Nov 2025
A23: Johann Roos | B23: 14000 | C23: 7000 | D23: 7000 | E23: 0.5 | F23: Nov 2025 | G23: Clients Nov 2025
A24: Ishaan/Elizabth | B24: 13300 | C24: 6300 | D24: 7000 | E24: 0.52631579 | F24: Nov 2025 | G24: Clients Nov 2025
A25: Androilla/ Praxia | B25: 21000 | C25: 11250 | D25: 9750 | E25: 0.46428571 | F25: Nov 2025 | G25: Clients Nov 2025
A26: Jacomina/Charl | B26: 3800 | C26: 9900 | D26: -6100 | E26: -1.6052632 | F26: Nov 2025 | G26: Clients Nov 2025
A27: Herman/Rene | B27: 4250 | C27: 2250 | D27: 2000 | E27: 0.47058824 | F27: Nov 2025 | G27: Clients Nov 2025
... A55: Scroope | B55: 3350 | C55: 0 | D55: 3350 | E55: 1 | F55: Apr 2026 | G55: Client Apr 2026

Sheet Caregiver Banking Details 
A1: Caregiver name | B1: Bank Name | C1: Account Number | D1: Account Type
A2: Linda Rapuluchukwa | B2: Capitec | C2: 1341317429 | D2: Savings | E2: Daily Rate
A3: Sophie Koga | B3: Bidvest Bank | C3: 78604588265 | D3: Current | E3: Daily Rate
A4: Joyce Mutambiranwa | B4: FNB | C4: 62785415649 | D4: Current | E4: Daily Rate
A5: Emily Mentula | B5: Capitec | C5: 1433103425 | D5: Savings | E5: Daily Rate
A6: Cynthia Makondo | B6: Capitec | C6: 1399500110 | D6: Savings | E6: Daily Rate
A7: Ruth Nnadi | B7: FNB | C7: 63124004473 | D7: Savings | E7: Daily Rate
A8: Christina Maluleka | B8: Standard Bank | C8: 10078950056 | D8: Current | E8: Daily Rate
A9: Mzee Mzwakhe | B9: FNB | C9: 63165744468 | D9: Current | E9: Daily Rate
A10: Susan Murire | B10: Capitec | C10: 1499687921 | D10: Savings | E10: Daily Rate
A11: Ndai Mapenyenye | B11: FNB | C11: 62353233168 | D11: Current | E11: Daily Rate
A12: Adaobi Ejikeme | B12: Standard Bank | C12: 10225922116 | D12: Current | E12: Daily Rate
A13: Merriam Maluleke | B13: Tyme Bank | C13: 51022803799 | D13: Savings | E13: Daily Rate
... A25: Matshidiso Leah Aphane | B25: Standard Bank | C25: 10198039598 | D25: Savings | E25: Set Rate- R7000
A26: Monique Bosch | B26: ABSA | C26: 9346827597 | D26: Current
A27: Nhlakanipho (Nipho) Tshabalala | B27: Capitec | C27: 1657265011 | D27: Savings | E27: Daily Rate
A28: Musa Zulu | B28: Standard Bank | C28: 10220227606 | D28: Current | E28: Daily Rate
A29: Busisiwe Mandiyanike | B29: Capitec | C29: 1824878654 | D29: Savings | E29: Daily Rate
A30: Julia Ramoroka | B30: Capitec | C30: 1699069881 | D30: Savings | E30: Daily Rate
A31: Martha Mashishi | B31: FNB | C31: 63184912434 | D31: Current | E31: Daily Rate
A32: Emilia Masvosva | B32: FNB | C32: 63187909420 | D32: Savings | E32: Daily Rate
A33: Sara Mdaka | B33: Standard Bank | C33: 10178989965 | D33: Savings | E33: Daily Rate
A34: Martha Sona | B34: Standard Bank | C34: 10155598854 | D34: Savings | E34: Daily Rate
A35: Mbali Ndaba | B35: Capitec | C35: 1498440809 | D35: Savings | E35: Daily Rate
A36: Philadelphia Mashaba | B36: Capitec | C36: 1664129756 | D36: Savings | E36: Daily Rate
A37: Annika Van Rensburg | B37: ABSA | C37: 9371060605 | D37: Savings | E37: 9600
A38: Fortunate Mabizela | B38: Capitec | C38: 1474680087 | D38: Savings | E38: Daily Rate
A39: Beauty Masopye | B39: Capitec | C39: 1289579669 | D39: Savings | E39: Daily Rate
A40: Thalitha Managa | B40: Capitec | C40: 1372172848 | D40: Savings | E40: Daily Rate
A41: Dolly Chauke | B41: Standard Bank | C41: 10140799891 | D41: Savings | E41: Daily Rate
A42: Annie Mabuto | B42: FNB | C42: 62417698836 | D42: Savings | E42: Daily Rate

Sheet Clients
A1: Patient Name | B1: Client Name | C1: Day Rate | D1: Monthly/ Weekly | E1: Day Shift/ Live In | F1: Full Time/ | G1: NPC/TCH | H1: Total Amount | I1: Active/ Not Active
A2: Pat Johnston | B2: Johnston | C2: 750 | D2: Monthly | E2: Live-In | F2: Mon- Fri | G2: NPC | I2: Active
A3: Tannie Annetjie | B3: Marisáne Gerber | C3: N/A | D3: Monthly | E3: Live-In | F3: Full Time | G3: NPC | H3: 22200 | I3: Not Active
A4: Bierman | B4: Dr Heleen Bieman Inc | C4: 800 | D4: Monthly | E4: Day Shift | F4: Mon- Fri | G4: TCH | I4: Active
A5: Boets | B5: M Boets | C5: 750 | D5: Monthly | E5: Day Shift | F5: Mon- Fri | G5: TCH | I5: Active
A6: Roos | B6: Andries Van der Merwe | C6: 700 | D6: Monthly | E6: Day Shift | F6: Mon- Fri | G6: TCH | I6: Not Active
A7: Le Roux | B7: Dr DA Le Roux Inc | C7: 750 | D7: Monthly | E7: Day Shift | F7: Every Thursday | G7: TCH | I7: Active
A8: Ras | B8: Marinus Ras | C8: 850 | D8: Monthly | E8: Live-In | F8: 14 Days Per Month | G8: TCH | H8: 11900 | I8: Active
A9: Tannie Klientjie | B9: Brenda Havenga | C9: N/A | D9: Monthly | E9: Live-In | F9: Full Time | G9: TCH | H9: 23250 | I9: Active
A10: Theron | B10: Quintus Theron | C10: 750 | D10: Monthly | E10: Day Shift | F10: Mon- Fri | G10: TCH | I10: Not Active
A11: Du Plessis | B11: Mathilnda Louisa Du Plessis | C11: N/A | D11: Monthly | E11: Day Shift | F11: Mon- Fri | G11: TCH | H11: 12500 | I11: Active
A12: Barnes | B12: Megan Louise Barnes | C12: N/A | D12: Monthly | E12: Day Shift | F12: 20 days per month | G12: TCH | H12: 13000 | I12: Active
A13: Sui Fon | B13: Julian Sam | C13: 678.57 | D13: Weekly | E13: Day Shift | F13: Discuss Weekly | G13: TCH | I13: Not Active
A14: Papau | B14: Angela Emily Piper | C14: 950 | D14: Weekly | E14: Live-In | F14: Full Time | G14: TCH | H14: 6650 | I14: Active
A15: Wessels | B15: Veron Wessels | C15: 1050 | D15: Monthly | E15: Day Shift | F15: Every Wednesday | G15: TCH | I15: Not Active
A16: Lotz | B16: Rene Lotz | C16: 800 | D16: Weekly | E16: Day Shift | F16: Mon- Fri | G16: TCH | I16: Not Active
A17: Scroope | B17: Jonathan Scroope | C17: 2500 | D17: As and when | E17: Live-In | F17: Fri-Mon | G17: TCH | I17: Active
A18: Diane Blumenthal | B18: Darren Blumenthal | C18: 900 | D18: As and when | E18: Night Shift | F18: 3 days | G18: TCH | I18: Not Active
A19: Cecily Hall | B19: Derke Hall | C19: 750 | D19: Monthly | E19: Day Shift | F19: Mon- Fri | G19: TCH | I19: Active
A20: Morrison | B20: Sandra Nell Morrison | C20: 750 | D20: Weekly | E20: Day Shift | F20: Mon- Fri | G20: TCH | I20: Not Active
A21: Anne Botha | B21: Berthe Botha | C21: 750 | D21: As and when | E21: Day Shift | G21: TCH | I21: Not Active
A22: Scholtz | B22: Dr CPT Scholtz | C22: 750 | E22: Day Shift | F22: Mon & Thur | G22: TCH | I22: Active
A23: Maria | B23: Yvonne Anne Burgum | C23: 750 | D23: Weekly | E23: Day Shift | F23: Mon, Wed, Fri | G23: TCH | I23: Active
A24: Ruth Place | B24: Dr Jean Meredith Place | C24: 800 | D24: As and when | E24: Day Shift | G24: TCH | I24: Active
A25: Roux | B25: Esme Kluckow | C25: 750 | D25: Monthly | E25: Day Shift | F25: Mon- Wed & Fri | G25: TCH | I25: Passed Away
A26: Carolina Richards | B26: Dawn Vivian Boyer de la Giroday | C26: 750 | D26: Monthly | E26: Day Shift | F26: Mon- Sun | G26: TCH | I26: Active
A27: Webb | B27: Sonja Sarantis | C27: 750 | D27: Weekly | E27: Day Shift | F27: Every Friday | G27: TCH | I27: Active
A28: Hardy | C28: 750
A29: Oosthuizen | B29: Hendrik Petrus Oosthuizen | C29: 750 | D29: Weekly | E29: Day Shift | F29: Mon- Fri | G29: TCH | I29: Active
A30: O'Neill | B30: Micheal O'Niel | C30: 850 | D30: Monthly | E30: Day Shift | F30: Mon-Sun | G30: TCH | I30: Active
A31: De Waal | B31: Erena Janse van Rensburg | C31: 950 | D31: Weekly | E31: Live-In | F31: Mon-Sun | G31: TCH | I31: Active
A32: Fisher | B32: Lynn Fisher | C32: N/A | D32: Monthly | E32: 2 Days per month | G32: TCH | H32: 5500 | I32: Active
A33: Nicolaas Alberts | B33: Nicolaas Alberts | C33: 950 | D33: As and when | G33: TCH
A34: Carli Peens | B34: Hendrik Peens | C34: 1500 | D34: Weekly | E34: 24 Hours | F34: Mon- Sun | G34: TCH | I34: Active
A35: Ingham | B35: Kenneth Ingham | C35: Night - R950 Day- R800 | D35: Daily | E35: 24 Hours | F35: Mon- Sun | G35: TCH | I35: Active
A36: Anna-Marie | B36: Helene Griffiths | C36: Live in - R950 | D36: As and when | E36: Live-In | G36: TCH | I36: Active
A37: Emce Bruinette | B37: Anton Styen | C37: Live in - R950 | D37: As and when | G37: TCH | I37: Active

Sheet Clients Nov 2025
A1: Johnstons | E1: Van Der Linde | I1: Hennie | M1: John Bierman | Q1: Hillery
A2: Income | E2: Income | I2: Income | M2: Income | Q2: Income
A3: Date: | C3: Payment | E3: Date: | G3: Payment | I3: Date: | K3: Payment | M3: Date: | O3: Payment | Q3: Date: | S3: Payment
A4: 45962 | C4: 24000 | E4: 45962 | G4: 22200 | I4: 45962 | K4: 4650 | M4: 45962 | O4: 16000 | Q4: 45962 | S4: 1900
I5: 45971 | K5: 4650 | Q5: 45990 | S5: 1900
I6: 45978 | K6: 4650
I7: 45985 | K7: 4650
C8: =SUM(C4:C7) | G8: =SUM(G4:G7) | K8: =SUM(K4:K7) | O8: =SUM(O4:O7) | S8: =SUM(S4:S7)
A9: Expenses | E9: Expenses | I9: Expenses | M9: Expenses | Q9: Expenses
A10: Date: | B10: Expense Name | C10: Amount | E10: Date: | F10: Expense Name | G10: Amount | I10: Date: | J10: Expense Name | K10: Amount | M10: Date: | N10: Expense Name | O10: Amount | Q10: Date: | R10: Expense Name | S10: Amount
A11: 45962 | B11: Linda | C11: 9600 | E11: 45962 | F11: Emily | G11: 3600 | I11: 45962 | J11: Cynthia | K11: 8750 | M11: 45962 | N11: Mzee | O11: 6450 | Q11: 45962 | R11: Tracy | S11: 2250
A12: 45962 | B12: Ada | C12: 6300 | E12: 45962 | F12: Joyce | G12: 900 | I12: 45962 | J12: Uber | K12: 4721
A13: 45962 | B13: Ada Stipens | C13: 3500 | E13: 45962 | F13: Emma | G13: 9000
E14: 45962 | F14: Uber | G14: 941
A23: Total Expense | C23: =SUM(C11:C22) | E23: Total Expense | G23: =SUM(G11:G22) | I23: Total Expense | K23: =SUM(K11:K22) | M23: Total Expense | O23: =SUM(O11:O22) | Q23: Total Expense | S23: =SUM(S11:S22)
A24: Income - Expense | C24: =MIN(C4-C23) | E24: Income - Expense | G24: =MIN(G4-G23) | I24: Income - Expense | K24: =MIN(K8-K23) | M24: Income - Expense | O24: =MIN(O4-O23) | Q24: Income - Expense | S24: =MIN(S8-S23)
A26: Van Vuuren | E26: Trevor Botes | I26: Johann Roos | M26: Ishaan/Elizabth | Q26: Androilla/ Praxia
A27: Income | E27: Income | I27: Income | M27: Income | Q27: Income
A28: Date: | C28: Payment | E28: Date: | G28: Payment | I28: Date: | K28: Payment | M28: Date: | O28: Payment | Q28: Date: | S28: Payment
A29: 45962 | C29: 5600 | E29: 45962 | G29: 3750 | I29: 45962 | K29: 7000 | M29: 45962 | O29: 6650 | Q29: 45962 | S29: 5250
A30: 45971 | C30: 5600 | E30: 45971 | G30: 3750 | I30: 45971 | K30: 7000 | M30: 45968 | O30: 6650 | Q30: 45973 | S30: 5250
A31: 45978 | C31: 5600 | E31: 45978 | G31: 3750 | Q31: 45981 | S31: 5250
A32: 45985 | C32: 3200 | E32: 45985 | G32: 3750 | Q32: 45987 | S32: 5250
A33: 45987 | C33: 3200
C34: =SUM(C29:C33) | G34: =SUM(G29:G32) | K34: =SUM(K29:K32) | O34: =SUM(O29:O32) | S34: =SUM(S29:S32)
A35: Expenses | E35: Expenses | I35: Expenses | M35: Expenses | Q35: Expenses
A36: Date: | B36: Expense Name | C36: Amount | E36: Date: | F36: Expense Name | G36: Amount | I36: Date: | J36: Expense Name | K36: Amount | M36: Date: | N36: Expense Name | O36: Amount | Q36: Date: | R36: Expense Name | S36: Amount
A37: 45962 | B37: Merriam | C37: 4500 | E37: 45962 | F37: Siphilisiwe (Patrica) | G37: 8450 | I37: 45962 | J37: Sylvia Nene | K37: 7000 | M37: 45962 | N37: Chrsitina | O37: 6300 | Q37: 45962 | R37: Sophia | S37: 11250
A38: 45962 | B38: Jane | C38: 6300
A49: Total Expense | C49: =SUM(C37:C48) | E49: Total Expense | G49: =SUM(G37:G48) | I49: Total Expense | K49: =SUM(K37:K48) | M49: Total Expense | O49: =SUM(O37:O48) | Q49: Total Expense | S49: =SUM(S37:S48)
A50: Income - Expense | C50: =MIN(C34-C49) | E50: Income - Expense | G50: =MIN(G34-G49) | I50: Income - Expense | K50: =MIN(K34-K49) | M50: Income - Expense | O50: =MIN(O34-O49) | Q50: Income - Expense | S50: =MIN(S34-S49)
A52: Jacomina/Charl | E52: Herman/Rene | I52: Lorraine Hatton | M52: Johanna Van Heerden | Q52: Dirk Le Roux
A53: Income | E53: Income | I53: Income | M53: Income | Q53: Income
A54: Date: | C54: Payment | E54: Date: | G54: Payment | I54: Date: | K54: Payment | M54: Date: | O54: Payment | Q54: Date: | S54: Payment
A55: 45962 | C55: 3800 | E55: 45966 | G55: 1700 | I55: 45977 | K55: 850 | M55: 45985 | O55: 4500 | Q55: 45992 | S55: 3000
E56: 45968 | G56: 2550 | I56: 45978 | K56: 850
C58: =SUM(C55:C57) | G58: =SUM(G55:G57) | K58: =SUM(K55:K57) | O58: =SUM(O55:O57)
A59: Expenses | E59: Expenses | I59: Expenses | M59: Expenses | S59: =SUM(S55:S58)
A60: Date: | B60: Expense Name | C60: Amount | E60: Date: | F60: Expense Name | G60: Amount | I60: Date: | J60: Expense Name | K60: Amount | M60: Date: | N60: Expense Name | O60: Amount | Q60: Expenses
A61: 45962 | B61: Refileo | C61: 4050 | E61: 45962 | F61: Joyce | G61: 2250 | I61: 45962 | J61: Sylvia Mutavhatsindi | K61: 750 | M61: 45962 | N61: Christina | O61: 2700 | Q61: Date: | R61: Expense Name | S61: Amount
...

Sheet Caregiver Nov 2025
C1: Linda Rapuluchukwa | D1: Sophie Koga | E1: Joyce Mutambiranwa | F1: Emily Mentula | G1: Cynthia Makondo | H1: Ruth Nnadi | I1: Christina Maluleka | J1: Mzee Mzwakhe | K1: Susan Murire | L1: Ndai Mapenyenye | M1: Adaobi Ejikeme | N1: Merriam Maluleke | O1: Jane Mokgaetsi Moekwa | P1: Sylvia Nene | Q1: Matodzi Sylvia Mutavhatsindi | R1: Siphilisiwe Nkala(Patricia) | S1: Refiloe Khuzwayo | T1: Mmamaswabi Emma Dhlamini | U1: Tracy Nothando Nyirenda
B2: Caregiver Price | C2: 600 | D2: 450 | E2: 450 | F2: 450 | G2: 350 | H2: 450 | I2: 450 | J2: 550 | K2: 450 | M2: 450 | N2: 450 | O2: 450 | P2: 350 | Q2: 450 | R2: 450 | S2: 450 | T2: 450 | U2: 450
A3: Date | B3: Days of Week
A4: 45962 | B4: Saturday | E4: Apie | G4: Hennie | I4: Elizabeth | K4: Jacomina | M4: Johnstons | O4: Linda | R4: Boets | U4: Hillery
A5: 45963 | B5: Sunday | E5: Apie | G5: Hennie | I5: Elizabeth | K5: Jacomina | M5: Johnstons | O5: Linda | U5: Hillery
A6: 45964 | B6: Monday | C6: Johnstons | F6: Apie | G6: Hennie | I6: Elizabeth | J6: Johan Bierman | K6: Jacomina | O6: Linda | P6: Roos | R6: Boets
A7: 45965 | B7: Tuesday | C7: Johnstons | F7: Apie | G7: Hennie | I7: Elizabeth | J7: Johan Bierman | K7: Jacomina | O7: Linda | P7: Roos | R7: Boets
A8: 45966 | B8: Wednesday | C8: Johnstons | E8: Rene | F8: Apie | I8: Elizabeth | J8: Johan Bierman | K8: Jacomina | O8: Linda | P8: Roos | R8: Boets
A9: 45967 | B9: Thursday | C9: Johnstons | D9: Androulla | E9: Rene | F9: Apie | G9: Hennie | I9: Elizabeth | J9: Johan Bierman | K9: Jacomina | O9: Linda | P9: Roos | R9: Boets
A10: 45968 | B10: Friday | D10: Androulla | E10: Rene | G10: Hennie | I10: Elizabeth | J10: Johan Bierman | K10: Jacomina | M10: Johnstons | O10: Van Vuuren | P10: Roos | R10: Boets | T10: Apie
A11: 45969 | B11: Saturday | D11: Androulla | E11: Rene | G11: Hennie | I11: Elizabeth | K11: Jacomina | M11: Johnstons | O11: Van Vuuren | T11: Apie
A12: 45970 | B12: Sunday | D12: Androulla | E12: Rene | I12: Elizabeth | M12: Johnstons | O12: Van Vuuren | S12: Jacomina | T12: Apie
A13: 45971 | B13: Monday | C13: Johnstons | D13: Androulla | F13: Apie | G13: Hennie | I13: Elizabeth | J13: Johan Bierman | O13: Van Vuuren | P13: Roos | R13: Boets | S13: Jacomina
A14: 45972 | B14: Tuesday | C14: Johnstons | D14: Androulla | F14: Apie | G14: Hennie | I14: Elizabeth | J14: Johan Bierman | O14: Van Vuuren | P14: Roos | R14: Boets | S14: Jacomina
A15: 45973 | B15: Wednesday | C15: Johnstons | D15: Androulla | F15: Apie | G15: Hennie | I15: Elizabeth | J15: Johan Bierman | O15: Van Vuuren | P15: Roos | R15: Boets | S15: Jacomina
A16: 45974 | B16: Thursday | C16: Johnstons | D16: Androulla | F16: Apie | G16: Hennie | I16: Elizabeth | J16: Johan Bierman | O16: Van Vuuren | P16: Roos | R16: Boets | S16: Jacomina
A17: 45975 | B17: Friday | D17: Androulla | G17: Hennie | J17: Johan Bierman | M17: Johnstons | N17: Van Vuuren | P17: Roos | R17: Boets | S17: Jacomina | T17: Apie
A18: 45976 | B18: Saturday | D18: Androulla | G18: Hennie | M18: Johnstons | N18: Van Vuuren | S18: Jacomina | T18: Apie
A19: 45977 | B19: Sunday | D19: Androulla | M19: Johnstons | N19: Van Vuuren | Q19: Hatton | S19: Jacomina | T19: Apie | U19: Hillery
A20: 45978 | B20: Monday | C20: Johnstons | D20: Androulla | G20: Hennie | J20: Johan Bierman | N20: Van Vuuren | P20: Roos | Q20: Hatton | R20: Boets | S20: Jacomina | T20: Apie
A21: 45979 | B21: Tuesday | C21: Johnstons | D21: Androulla | G21: Hennie | J21: Johan Bierman | K21: Jacomina | N21: Van Vuuren | P21: Roos | R21: Boets | T21: Apie
A22: 45980 | B22: Wednesday | C22: Johnstons | D22: Androulla | G22: Hennie | J22: Johan Bierman | K22: Jacomina | N22: Van Vuuren | P22: Roos | R22: Boets | T22: Apie
A23: 45981 | B23: Thursday | C23: Johnstons | D23: Androulla | G23: Hennie | J23: Johan Bierman | K23: Jacomina | N23: Van Vuuren | P23: Roos | R23: Boets | T23: Apie
A24: 45982 | B24: Friday | D24: Androulla | G24: Hennie | K24: Jacomina | M24: Johnstons | N24: Van Vuuren | P24: Roos | R24: Boets | T24: Apie
A25: 45983 | B25: Saturday | D25: Androulla | G25: Hennie | K25: Jacomina | M25: Johnstons | N25: Van Vuuren | T25: Apie
A26: 45984 | B26: Sunday | D26: Androulla | M26: Johnstons | N26: Van Vuuren | T26: Apie
A27: 45985 | B27: Monday | C27: Johnstons | D27: Androulla | G27: Hennie | J27: Johan Bierman | O27: Van Vuuren | P27: Roos | R27: Boets | T27: Apie
A28: 45986 | B28: Tuesday | C28: Johnstons | D28: Androulla | G28: Hennie | I28: Johanna | J28: Johan Bierman | O28: Van Vuuren | P28: Roos | R28: Boets | T28: Apie
A29: 45987 | B29: Wednesday | C29: Johnstons | D29: Androulla | G29: Hennie | I29: Johanna | J29: Johan Bierman | O29: Van Vuuren | P29: Roos | R29: Boets | T29: Apie
A30: 45988 | B30: Thursday | C30: Johnstons | D30: Androulla | G30: Hennie | I30: Johanna | J30: Johan Bierman | O30: Van Vuuren | P30: Roos | R30: Boets | T30: Apie
A31: 45989 | B31: Friday | D31: Androulla | G31: Hennie | I31: Johanna | J31: Johan Bierman | M31: Johnstons | O31: Van Vuuren | P31: Roos | R31: Boets | T31: Apie
A32: 45990 | B32: Saturday | D32: Androulla | G32: Hennie | I32: Johanna | M32: Johnstons | O32: Van Vuuren | T32: Apie | U32: Hillery
A33: 45991 | B33: Sunday | D33: Androulla | I33: Johanna | M33: Johnstons | O33: Van Vuuren | T33: Apie | U33: Hillery
A34: Days Worked | C34: 16 | D34: 25 | E34: 7 | F34: 8 | G34: 25 | I34: 20 | J34: 19 | K34: 13 | M34: 14 | N34: 10 | O34: 20 | P34: 20 | Q34: 2 | R34: 21 | S34: 9 | T34: 20 | U34: 5
A35: Money Borrowed | J35: 4000 | Q35: 150 | R35: 1000
A36: Total Amount | B36: =SUM(C36:U36) | C36: =C2*C34 | D36: =D2*D34 | E36: =E34*E2 | F36: =F34*F2 | G36: =G34*G2 | I36: =I2*I34 | J36: =J2*J34-J35 | K36: =K2*K34 | M36: =M2*M34 | N36: =N2*N34 | O36: =O2*O34 | P36: =P2*P34 | Q36: =Q2*Q34-Q35 | R36: =R2*R34-R35 | S36: =S2*S34 | T36: =T2*T34 | U36: =U2*U34
A39: Availble Caregiver | C39: =SUM(C36+D36+E36+F36+G36+I36+J36+K36+M36)
A40: Tabea
A41: Tracy
A42: Lerato | C42: =MIN(B36-C39)

Sheet Clients Dec 2025
A1: Johnstons | E1: Van Der Linde | I1: Hennie | M1: John Bierman | Q1: Hillery
A2: Income | E2: Income | I2: Income | M2: Income | Q2: Income
A3: Date: | C3: Payment | E3: Date: | G3: Payment | I3: Date: | K3: Payment | M3: Date: | O3: Payment | Q3: Date: | S3: Payment
A4: 45992 | B4: invoiced | C4: 24800 | E4: 45992 | F4: invoiced | G4: 22200 | I4: 45996 | J4: invoiced | K4: 4650 | M4: 45992 | N4: invoiced | O4: 18400 | Q4: 45993 | R4: invoiced | S4: 2850
C8: =SUM(C4:C7) | G8: =SUM(G4:G7) | K8: =SUM(K4:K7) | O8: =SUM(O4:O7) | S8: =SUM(S4:S7)
A9: Expenses | E9: Expenses | I9: Expenses | M9: Expenses | Q9: Expenses
A10: Date: | B10: Expense Name | C10: Amount | E10: Date: | F10: Expense Name | G10: Amount | I10: Date: | J10: Expense Name | K10: Amount | M10: Date: | N10: Expense Name | O10: Amount | Q10: Date: | R10: Expense Name | S10: Amount
A11: 45992 | B11: Linda | C11: 9600 | E11: 45992 | F11: Emily | G11: 9450 | I11: 45992 | J11: Cynthia | K11: 4200 | M11: 45992 | N11: Mzee | O11: 9400 | Q11: 1 dce | R11: Tracy | S11: 1800
A12: 45992 | B12: Ada | C12: 6750 | E12: 45992 | F12: Emma | G12: 4500 | I12: 45992 | J12: Uber | K12: 1216
E13: 45992 | F13: Uber | G13: 1589
A23: Total Expense | C23: =SUM(C11:C22) | E23: Total Expense | G23: =SUM(G11:G22) | I23: Total Expense | K23: =SUM(K11:K22) | M23: Total Expense | O23: =SUM(O11:O22) | Q23: Total Expense | S23: =SUM(S11:S22)
A24: Income - Expense | C24: =MIN(C4-C23) | E24: Income - Expense | G24: =MIN(G4-G23) | I24: Income - Expense | K24: =MIN(K4-K23) | M24: Income - Expense | O24: =MIN(O4-O23) | Q24: Income - Expense | S24: =MIN(S4-S23)
A26: Julian Sam | E26: Trevor Botes | I26: Johann Roos | M26: Dirk Le Roux | Q26: Androilla/ Praxia
A27: Income | E27: Income | I27: Income | M27: Income | Q27: Income
A28: Date: | C28: Payment | E28: Date: | G28: Payment | I28: Date: | K28: Payment | M28: Date: | O28: Payment | Q28: Date: | S28: Payment
A29: 45996 | B29: invoiced | C29: 5250 | E29: 45996 | F29: invoiced | G29: 3750 | I29: 45992 | J29: 1 Dec -12 Dec | K29: 7000 | M29: 46000 | N29: invoiced | O29: 5900 | Q29: 45992 | R29: invoiced | S29: 5250
A30: 46003 | B30: invoiced | C30: 5250 | E30: 46003 | F30: invoiced | G30: 3750 | I30: 46002 | J30: Invocied | K30: 4900 | M30: 46006 | N30: invoiced | O30: 4950 | Q30: 46000 | R30: invoiced | S30: 2250
A31: 46010 | C31: 4750 | E31: 46010 | F31: invoiced | G31: 3000
A32: 46017 | E32: 46017 | F32: invoiced | G32: 3000
E33: 46020 | F33: invoiced | G33: 3000
C34: =SUM(C29:C32) | G34: =SUM(G29:G33) | K34: =SUM(K29:K33) | O34: =SUM(O29:O32) | S34: =SUM(S29:S32)
A35: Expenses | E35: Expenses | I35: Expenses | M35: Expenses | Q35: Expenses
A36: Date: | B36: Expense Name | C36: Amount | E36: Date: | F36: Expense Name | G36: Amount | I36: Date: | J36: Expense Name | K36: Amount | M36: Date: | N36: Expense Name | O36: Amount | Q36: Date: | R36: Expense Name | S36: Amount
A37: 45992 | B37: Reflioe | C37: 6300 | E37: 45992 | F37: Siphilisiwe (Patrica) | G37: 8750 | I37: 45992 | J37: Sylvia Nene | K37: 5150 | M37: 45992 | N37: Ruth | O37: 6750 | Q37: 45962 | R37: Sophia | S37: 5850
A38: 45992 | B38: Siphethokhuhle | C38: 3150
A49: Total Expense | C49: =SUM(C37:C48) | E49: Total Expense | G49: =SUM(G37:G48) | I49: Total Expense | K49: =SUM(K37:K48) | M49: Total Expense | O49: =SUM(O37:O48) | Q49: Total Expense | S49: =SUM(S37:S48)
A50: Income - Expense | C50: =MIN(C34-C49) | E50: Income - Expense | G50: =MIN(G34-G49) | I50: Income - Expense | K50: =MIN(K34-K49) | M50: Income - Expense | O50: =MIN(O34-O49) | Q50: Income - Expense | S50: =MIN(S34-S37)
A52: Lucy | E52: Mia Rus | I52: Johanna Van Heerden | M52: Andre Theron | Q52: Angela/ Dimitri Paoadopoulos
A53: Income | E53: Income | I53: Income | M53: Income | Q53: Income
A54: Date: | C54: Payment | E54: Date: | G54: Payment | I54: Date: | K54: Payment | M54: Date: | O54: Payment | Q54: Date: | S54: Payment
A55: 46001 | B55: invoiced | C55: 2250 | E55: 45992 | G55: 9387 | I55: 45992 | J55: invoiced | K55: 23250 | M55: 45992 | N55: invoiced | O55: 5250 | Q55: 46008 | R55: invoiced | S55: 13300
A56: 46006 | B56: invoiced | C56: 3000 | M56: 46006 | N56: invoiced | O56: 10700
C59: =SUM(C55:C58) | G59: =SUM(G55:G58) | K59: =SUM(K55:K58) | O59: =SUM(O55:O58) | S59: =SUM(S55:S58)
A60: Expenses | E60: Expenses | I60: Expenses | M60: Expenses | Q60: Expenses
A61: Date: | B61: Expense Name | C61: Amount | E61: Date: | F61: Expense Name | G61: Amount | I61: Date: | J61: Expense Name | K61: Amount | M61: Date: | N61: Expense Name | O61: Amount | Q61: Date: | R61: Expense Name | S61: Amount
B62: Joyce | C62: 3150 | E62: 45992 | F62: Marion | G62: 4950 | I62: 45992 | J62: Christina | K62: 9450 | M62: 45992 | N62: Rebecca | O62: 2700 | Q62: 45992 | R62: Tracy | S62: 5850
J63: Jane | K63: 4500 | M63: 45992 | N63: Sophia | O63: 3600
M64: 45992 | N64: Joyce | O64: 3159
A74: Total Expense | C74: =SUM(C62:C72) | E74: Total Expense | G74: =SUM(G62:G66) | I74: Total Expense | K74: =SUM(K62:K73) | M74: Total Expense | O74: =SUM(O62:O73) | Q74: Total Expense | S74: =SUM(S62:S67)
A75: Income - Expense | C75: =MIN(C59-C74) | E75: Income - Expense | G75: =MIN(G59-G74) | I75: Income - Expense | K75: =MIN(K59-K74) | M75: Income - Expense | O75: =MIN(O59-O74) | Q75: Income - Expense | S75: =MIN(S59-S74)
...

Sheet Caregiver Dec 2025
C1: Linda Rapuluchukwa | D1: Sophie Koga | E1: Joyce Mutambiranwa | F1: Emily Mentula | G1: Cynthia Makondo | H1: Ruth Nnadi | I1: Christina Maluleka | J1: Mzee Mzwakhe | K1: Susan Murire | L1: Ndai Mapenyenye | M1: Adaobi Ejikeme | N1: Merriam Maluleke | O1: Jane Mokgaetsi Moekwa | P1: Sylvia Nene | Q1: Matodzi Sylvia Mutavhatsindi | R1: Siphilisiwe Nkala(Patricia) | S1: Refiloe Khuzwayo | T1: Mmamaswabi Emma Dhlamini | U1: Tracy Nothando Nyirenda | V1: Marion Goeda | W1: Rebecca Samba | X1: Siphethokhuhle Nkomo
B2: Caregiver Price | C2: 600 | D2: 450 | E2: 450 | F2: 450 | G2: 350 | H2: 450 | I2: 450 | K2: 450 | M2: 450 | N2: 334 | O2: 450 | P2: 305 | Q2: 450 | R2: 450 | S2: 450 | T2: 450 | U2: 450 | V2: 450 | W2: 450 | X2: 450
A3: Date | B3: Days of Week
A4: 45992 | B4: Monday | C4: Johnstons | D4: Androulla | G4: Hennie | I4: Van Heerden | J4: Bierman | O4: Van Vuuren | P4: Roos | R4: Botes | T4: Apie | U4: Hillery
A5: 45993 | B5: Tuesday | C5: Johnstons | D5: Androulla | F5: Apie | G5: Hennie | I5: Van Heerden | J5: Bierman | P5: Roos | R5: Botes
A6: 45994 | B6: Wednesday | C6: Johnstons | D6: Androulla | F6: Apie | G6: Hennie | I6: Van Heerden | J6: Bierman | P6: Roos | R6: Botes
A7: 45995 | B7: Thursday | C7: Johnstons | D7: Androulla | F7: Apie | G7: Hennie | H7: Le Roux | I7: Van Heerden | J7: Bierman | P7: Roos | R7: Botes
A8: 45996 | B8: Friday | D8: Androulla | F8: Apie | G8: Hennie | I8: Van Heerden | J8: Bierman | M8: Johnstons | P8: Roos | R8: Botes
A9: 45997 | B9: Saturday | D9: Androulla | F9: Apie | G9: Hennie | I9: Van Heerden | M9: Johnstons
A10: 45998 | B10: Sunday | D10: Androulla | F10: Apie | I10: Van Heerden | M10: Johnstons | U10: Hillery
A11: 45999 | B11: Monday | D11: Androulla | F11: Apie | G11: Hennie | I11: Van Heerden | J11: Bierman | M11: Johnstons | P11: Roos | R11: Botes | S11: Sui Fon
A12: 46000 | B12: Tuesday | D12: Androulla | F12: Apie | G12: Hennie | I12: Van Heerden | J12: Bierman | M12: Johnstons | P12: Roos | R12: Botes | S12: Sui Fon
A13: 46001 | B13: Wednesday | C13: Johnstons | D13: Androulla | F13: Apie | G13: Hennie | H13: Le Roux | I13: Van Heerden | J13: Bierman | P13: Roos | R13: Botes | S13: Sui Fon | V13: Ras
A14: 46002 | B14: Thursday | C14: Johnstons | D14: Androulla | F14: Apie | G14: Hennie | H14: Le Roux | I14: Van Heerden | J14: Bierman | P14: Roos | R14: Botes | S14: Sui Fon | V14: Ras | W14: Theron
A15: 46003 | B15: Friday | C15: Johnstons | D15: Androulla | E15: Patricia | G15: Hennie | H15: Le Roux | I15: Van Heerden | J15: Bierman | P15: Roos | R15: Botes | S15: Sui Fon | T15: Apie | W15: Theron
A16: 46004 | B16: Saturday | C16: Johnstons | D16: Androulla | E16: Patricia | G16: Hennie | H16: Le Roux | I16: Van Heerden | S16: Sui Fon | T16: Apie | U16: Hillery | W16: Theron
A17: 46005 | B17: Sunday | C17: Johnstons | E17: Patricia | H17: Le Roux | I17: Van Heerden | S17: Sui Fon | T17: Apie | U17: Hillery | W17: Theron
A18: 46006 | B18: Monday | E18: Patricia | F18: Apie | H18: Le Roux | J18: Bierman | M18: Johnstons | O18: Van Heerden | P18: Roos | R18: Botes | S18: Sui Fon | W18: Theron
A19: 46007 | B19: Tuesday | E19: Patricia | F19: Apie | H19: Le Roux | J19: Bierman | M19: Johnstons | O19: Van Heerden | P19: Roos | S19: Sui Fon | W19: Theron
A20: 46008 | B20: Wednesday | D20: Theron | E20: Patricia | F20: Apie | H20: Le Roux | J20: Bierman | M20: Johnstons | O20: Van Heerden | P20: Roos | R20: Botes | S20: Sui Fon | V20: Ras
A21: 46009 | B21: Thursday | D21: Theron | E21: Patricia | F21: Apie | H21: Le Roux | J21: Bierman | M21: Johnstons | O21: Van Heerden | P21: Roos | R21: Botes | S21: Sui Fon | U21: Paoadopoulos | V21: Malanie
A22: 46010 | B22: Friday | C22: Johnstons | D22: Theron | H22: Le Roux | J22: Bierman | O22: Van Heerden | P22: Roos | R22: Botes | S22: Sui Fon | T22: Apie | U22: Paoadopoulos | V22: Ras
A23: 46011 | B23: Saturday | C23: Johnstons | D23: Theron | H23: Le Roux | O23: Van Heerden | R23: Botes | S23: Sui Fon | T23: Apie | U23: Paoadopoulos | V23: Ras
A24: 46012 | B24: Sunday | C24: Johnstons | D24: Theron | H24: Le Roux | O24: Van Heerden | S24: Sui Fon | T24: Apie | U24: Paoadopoulos | V24: Ras
A25: 46013 | B25: Monday | C25: Johnstons | D25: Theron | H25: Le Roux | I25: Van Heerden | J25: Bierman | N25: Scroope | P25: Roos | R25: Botes | T25: Apie | U25: Paoadopoulos | V25: Ras | X25: Sui Fon
A26: 46014 | B26: Tuesday | D26: Theron | F26: Apie | H26: Le Roux | I26: Van Heerden | J26: Bierman | M26: Johnstons | N26: Scroope | P26: Roos | R26: Botes | U26: Paoadopoulos | V26: Ras | X26: Sui Fon
A27: 46015 | B27: Wednesday | E27: Theron | F27: Apie | I27: Van Heerden | J27: Bierman | M27: Johnstons | N27: Scroope | O27: Nozi | R27: Botes | U27: Paoadopoulos | X27: Sui Fon
A28: 46016 | B28: Thursday | E28: Theron | F28: Apie | I28: Van Heerden | J28: Bierman | M28: Johnstons | N28: Scroope | O28: Nozi | U28: Paoadopoulos
A29: 46017 | B29: Friday | E29: Theron | F29: Apie | I29: Van Heerden | J29: Bierman | M29: Johnstons | N29: Scroope | O29: Nozi | U29: Paoadopoulos | V29: Trish-600
A30: 46018 | B30: Saturday | E30: Theron | F30: Apie | I30: Van Heerden | M30: Johnstons | N30: Scroope | U30: Paoadopoulos | X30: Sui Fon
A31: 46019 | B31: Sunday | E31: Theron | F31: Apie | I31: Van Heerden | M31: Johnstons | N31: Scroope | U31: Paoadopoulos | X31: Sui Fon
A32: 46020 | B32: Monday | C32: Johnstons | E32: Theron | F32: Apie | J32: Bierman | N32: Scroope | O32: Van Heerden | R32: Botes | U32: Paoadopoulos | V32: Ras | X32: Sui Fon
A33: 46021 | B33: Tuesday | C33: Johnstons | E33: Theron | J33: Bierman | N33: Scroope | O33: Van Heerden | R33: Botes | T33: Apie | U33: Paoadopoulos | V33: Ras | X33: Sui Fon
A34: 46022 | B34: Wednesday | C34: Johnstons | D34: Theron | E34: Paoadopoulos | J34: Bierman | N34: Scroope | O34: Van Heerden | R34: Botes | T34: Apie | V34: Ras
A35: Days Worked | C35: 16 | D35: 21 | E35: 15 | F35: 21 | G35: 12 | H35: 15 | I35: 21 | J35: 23 | M35: 15 | N35: 10 | O35: 14 | P35: 17 | R35: 21 | S35: 14 | T35: 10 | U35: 17 | V35: 13 | W35: 6 | X35: 7
V36: 150
A37: Money Borrowed | J37: 1600 | O37: 272 | R37: 700 | U37: 250 | V37: 1000 | W37: 2550
A38: Total Amount | B38: =SUM(C38:AL38) | C38: =C2*C35 | D38: =D2*D35 | E38: =E35*E2 | F38: =F35*F2 | G38: =G35*G2 | H38: =H2*H35 | I38: =I2*I35 | J38: 9400 | K38: =K2*K35 | M38: =M2*M35 | N38: =N2*N35 | O38: =O2*O35-O37 | P38: =P2*P35 | Q38: =Q2*Q35-Q37 | R38: =R2*R35-R37 | S38: =S2*S35 | T38: =T2*T35 | U38: =U2*U35-U37 | V38: =SUM(V2*V35-V37+V36) | W38: =W2*W35-W37 | X38: =X2*X35-X37
D41: Andre NPC | E41: =SUM(C38+D38+E38+F38+G38+H38+I38+J38+K38+L38+M38+W38)
D42: Donnay TCH | E42: =SUM(N38+O38+P38+Q38+R38+S38+T38+U38+V38+X38)

Sheet Clients Jan 2026
A1: Johnstons- monthly | E1: Van Der Linde- monthly | I1: Rene Lotz/ Wilhelm | M1: John Bierman- monthly | Q1: Natasha Naranjee | U1: Scroope
A2: Income | E2: Income | I2: Income | M2: Income | Q2: Income | U2: Income
A3: Date: | C3: Payment | E3: Date: | G3: Payment | I3: Date: | K3: Payment | M3: Date: | O3: Payment | Q3: Date: | S3: Payment | U3: Date: | W3: Payment
A4: 45658 | B4: Invoiced NPC | C4: 23250 | E4: 45658 | F4: Invoiced NPC | G4: 22200 | I4: 46030 | J4: invoiced | K4: 7300 | M4: 45658 | N4: Invoiced TCH | O4: 17600 | Q4: 46029 | R4: Invoived | S4: 3400 | U4: 46023 | V4: invoiced | W4: 1500
I5: 46038 | J5: invoiced | K5: 5900 | Q5: 46032 | R5: Invoived | S5: 6600 | U5: 46048 | V5: invoiced | W5: 2500
C8: =SUM(C4:C7) | G8: =SUM(G4:G7) | K8: =SUM(K4:K7) | O8: =SUM(O4:O7) | S8: =SUM(S4:S7) | W8: =SUM(W4:W7)
A9: Expenses | E9: Expenses | I9: Expenses | M9: Expenses | Q9: Expenses | U9: Expenses
A10: Date: | B10: Expense Name | C10: Amount | E10: Date: | F10: Expense Name | G10: Amount | I10: Date: | J10: Expense Name | K10: Amount | M10: Date: | N10: Expense Name | O10: Amount | Q10: Date: | R10: Expense Name | S10: Amount | U10: Date: | V10: Expense Name | W10: Amount
A11: 45992 | B11: Linda | E11: 45992 | F11: Emily | M11: 45992 | Q11: 46023 | R11: Marion | V11: Merriam
A12: 45992 | B12: Ada | E12: 45992 | F12: Emma | R12: Syliva Nene
B13: Sylive | E13: 45992 | F13: Uber | R13: Joyce
A23: Total Expense | C23: =SUM(C11:C22) | E23: Total Expense | G23: =SUM(G11:G22) | I23: Total Expense | K23: =SUM(K11:K22) | M23: Total Expense | O23: =SUM(O11:O22) | Q23: Total Expense | S23: =SUM(S11:S22) | U23: Total Expense | W23: =SUM(W11:W14)
A24: Income - Expense | C24: =MIN(C4-C23) | E24: Income - Expense | G24: =MIN(G4-G23) | I24: Income - Expense | K24: =MIN(K4-K23) | M24: Income - Expense | O24: =MIN(O4-O23) | Q24: Income - Expense | S24: =MIN(S4-S23) | U24: Income - Expense | W24: =MIN(W8-W23)
A26: Julian Sam | E26: Trevor Botes- monthly | I26: Johann Roos | M26: Dirk Le Roux- monthly | Q26: Kotie Jacoba | U26: Christina Botha (Transfer)
A27: Income | E27: Income | I27: Income | M27: Income | Q27: Income | U27: Income
A28: Date: | C28: Payment | E28: Date: | G28: Payment | I28: Date: | K28: Payment | M28: Date: | O28: Payment | Q28: Date: | S28: Payment | U28: Date: | W28: Payment
A29: 45658 | B29: Invoiced | C29: 2036 | E29: 45662 | F29: invoiced | G29: 14250 | M29: 45658 | N29: invoiced TCH | O29: 3750 | Q29: 45658 | R29: invocied | S29: 3850 | U29: 46037 | W29: 700
A30: 46027 | B30: Invoiced | C30: 3393 | Q30: 45662 | R30: invoiced | S30: 3750
A31: 46030 | B31: Invoiced | C31: 2715 | Q31: 46030 | R31: invocied | S31: 600
A32: 46046 | B32: Invoiced | C32: 2036
C33: =SUM(C29:C32) | G33: =SUM(G29:G32) | K33: =SUM(K29:K32) | O33: =SUM(O29:O32) | S33: =SUM(S29:S32) | W33: =SUM(W29:W32)
A34: Expenses | E34: Expenses | I34: Expenses | M34: Expenses | Q34: Expenses | U34: Expenses
A35: Date: | B35: Expense Name | C35: Amount | E35: Date: | F35: Expense Name | G35: Amount | I35: Date: | J35: Expense Name | K35: Amount | M35: Date: | N35: Expense Name | O35: Amount | Q35: Date: | R35: Expense Name | S35: Amount | U35: Date: | V35: Expense Name | W35: Amount
A36: 45992 | B36: Siphe | E36: 45992 | F36: Siphilisiwe (Patrica) | I36: 45992 | M36: 45992 | Q36: 45658 | U36: 45658 | V36: Lina
A37: 45992
A48: Total Expense | C48: =SUM(C36:C47) | E48: Total Expense | G48: =SUM(G36:G47) | I48: Total Expense | M48: Total Expense | Q48: Total Expense | S48: 14838 | U48: Total Expense | W48: 14838
A49: Income - Expense | C49: =MIN(C29-C48) | E49: Income - Expense | G49: =MIN(G29-G48) | I49: Income - Expense | M49: Income - Expense | Q49: Income - Expense | S49: 7362 | U49: Income - Expense | W49: 7362
A51: Julia Ann | E51: Mia Rus- monthly | I51: Johanna Van Heerden- monthly | M51: Andre Theron- monthly | Q51: Angela/ Dimitri Paoadopoulos- weekly | U51: Du Plessis
A52: Income | E52: Income | I52: Income | M52: Income | Q52: Income | U52: Income
A53: Date: | C53: Payment | E53: Date: | G53: Payment | I53: Date: | K53: Payment | M53: Date: | O53: Payment | Q53: Date: | S53: Payment | U53: Date: | W53: Payment
A54: 46027 | B54: invoiced | C54: 6000 | E54: 46029 | F54: invoiced | G54: 11900 | I54: 45658 | J54: Invoiced TCH | K54: 23250 | M54: 45658 | N54: invoiced | O54: 5450 | Q54: 45658 | R54: invoiced | S54: 6650 | U54: 46042 | V54: invoiced | W54: 5114
A55: 46031 | B55: invoiced | C55: 12000 | M55: 46030 | N55: invoiced | O55: 12750 | Q55: 46030 | R55: invoiced | S55: 6650
Q56: 46034 | R56: invoiced | S56: 6650
Q57: 46044 | R57: invoiced | S57: 6650
Q58: 46051 | R58: invoiced | S58: 6650
C59: =SUM(C54:C57) | G59: =SUM(G54:G58) | K59: =SUM(K54:K57) | O59: =SUM(O54:O57) | S59: =SUM(S54:S58) | W59: =SUM(W54:W57)
A60: Expenses | E60: Expenses | I60: Expenses | M60: Expenses | Q60: Expenses | U60: Expenses
A61: Date: | B61: Expense Name | C61: Amount | E61: Date: | F61: Expense Name | G61: Amount | I61: Date: | J61: Expense Name | K61: Amount | M61: Date: | N61: Expense Name | O61: Amount | Q61: Date: | R61: Expense Name | S61: Amount | U61: Date: | V61: Expense Name | W61: Amount
A62: 46023 | B62: Cynthia | E62: 45992 | F62: Marion | I62: 45658 | J62: Christina | M62: 45658 | N62: Sophia | Q62: 45992 | R62: Tracy | U62: 45658
B63: Jane | I63: 45658 | J63: Lina | M63: 45658 | R63: Joyce
...

Sheet Caregiver Jan 2026
C1: Linda Rapuluchukwa | D1: Sophie Koga | E1: Joyce Mutambiranwa | F1: Emily Mentula | G1: Cynthia Makondo | H1: Ruth Nnadi | I1: Christina Maluleka | J1: Susan Murire | K1: Ndai Mapenyenye | L1: Adaobi Ejikeme | M1: Merriam Maluleke | N1: Jane Mokgaetsi Moekwa | O1: Sylvia Nene | P1: Matodzi Sylvia Mutavhatsindi | Q1: Siphilisiwe Nkala(Patricia) | R1: Refiloe Khuzwayo | S1: Mmamaswabi Emma Dhlamini | T1: Tracy Nothando Nyirenda | U1: Marion Goeda | V1: Siphethokhuhle Nkomo | W1: Lina Raphahlela | X1: Matshidiso Leah Aphane | Y1: Monique Bosch | Z1: Nhlakanipho (Nipho) Tshabalala
B2: Caregiver Price | C2: 600 | D2: 450 | E2: 500 | F2: 450 | G2: 450 | H2: 450 | I2: 450 | J2: 450 | L2: 450 | M2: 334 | N2: 450 | O2: 450 | P2: 450 | Q2: 450 | R2: 450 | S2: 450 | T2: 450 | U2: 450 | V2: 450 | W2: 450 | X2: 350 | Y2: 283 | Z2: 500
A3: Date | B3: Days of Week
A4: 45658 | B4: Thursday | C4: Johnstons | D4: Theron | E4: Paoadopoulos | H4: Le Roux | M4: Scroope | N4: Klientjie | S4: Apie | U4: Ras
A5: 45659 | B5: Friday | D5: Theron | E5: Paoadopoulos | L5: Johnstons | M5: Scroope | N5: Klientjie | S5: Apie | U5: Ras | V5: Sui Fon
A6: 45660 | B6: Saturday | D6: Theron | E6: Paoadopoulos | J6: Kotie- half | L6: Johnstons | M6: Scroope | N6: Klientjie | S6: Apie | U6: Ras | V6: Sui Fon
A7: 45661 | B7: Sunday | D7: Theron | E7: Paoadopoulos | L7: Johnstons | M7: Scroope | N7: Klientjie | S7: Apie | U7: Ras | V7: Sui Fon
A8: 45662 | B8: Monday | C8: Johnstons | D8: Theron | E8: Paoadopoulos | F8: Apie | G8: Julia Ann | I8: Klientjie | J8: Kotie | M8: Scroope | Q8: Boets | U8: Kotie | V8: Sui Fon
A9: 45663 | B9: Tuesday | C9: Johnstons | D9: Theron | E9: Paoadopoulos | F9: Apie | G9: Julia Ann | I9: Klientjie | M9: Scroope | Q9: Boets | V9: Sui Fon
A10: 45664 | B10: Wednesday | C10: Johnstons | D10: Theron | E10: Paoadopoulos | F10: Apie | G10: Julia Ann | I10: Klientjie | M10: Scroope | Q10: Boets | V10: Sui Fon
A11: 45665 | B11: Thursday | C11: Johnstons | D11: Theron | E11: Paoadopoulos | F11: Apie | G11: Julia Ann | H11: Le Roux | I11: Klientjie | M11: Scroope | Q11: Boets | U11: Natasha | V11: Sui Fon
A12: 45666 | B12: Friday | C12: Johnstons | D12: Theron | E12: Paoadopoulos | G12: Julia Ann | H12: Lotz | I12: Klientjie | M12: Scroope | O12: Johnstons | Q12: Boets | S12: Apie | U12: Natasha | V12: Sui Fon
A13: 45667 | B13: Saturday | E13: Paoadopoulos | H13: Lotz | I13: Klientjie | L13: Johnstons | M13: Scroope | N13: Julia Ann | S13: Apie | U13: Natasha
A14: 45668 | B14: Sunday | E14: Paoadopoulos | H14: Lotz | I14: Klientjie | L14: Johnstons | M14: Scroope | N14: Julia Ann | O14: Natasha | S14: Apie | U14: Natasha
A15: 45669 | B15: Monday | D15: Theron | F15: Apie | H15: Lotz | I15: Klientjie | J15: Bierman | L15: Johnstons | M15: Scroope-R450 | N15: Julia Ann | O15: Natasha | T15: Paoadopoulos | U15: Ras | V15: Sui Fon
A16: 45670 | B16: Tuesday | D16: Theron | F16: Apie | H16: Lotz | I16: Klientjie | J16: Bierman | L16: Johnstons | N16: Julia Ann | O16: Natasha | T16: Paoadopoulos | U16: Ras | V16: Sui Fon
A17: 45671 | B17: Wednesday | D17: Theron | E17: Natasha | F17: Apie | I17: Klientjie | J17: Bierman | L17: Johnstons | N17: Julia Ann | Q17: Boets | S17: Lotz | T17: Paoadopoulos | U17: Ras | V17: Sui Fon
A18: 45672 | B18: Thursday | C18: Johnstons | D18: Theron | E18: Natasha | F18: Apie | I18: Klientjie | J18: Bierman | N18: Julia Ann | Q18: Boets | S18: Lotz | T18: Paoadopoulos | U18: Ras | V18: Sui Fon | W18: Christina
A19: 45673 | B19: Friday | C19: Johnstons | D19: Theron | H19: Lotz | I19: Klientjie | J19: Bierman | N19: Julia Ann | Q19: Boets | S19: Apie | T19: Paoadopoulos | U19: Ras
A20: 45674 | B20: Saturday | C20: Johnstons | H20: Lotz | I20: Klientjie | N20: Julia Ann | S20: Apie | T20: Paoadopoulos | U20: Ras
A21: 45675 | B21: Sunday | C21: Johnstons | H21: Lotz | I21: Klientjie | N21: Julia Ann | S21: Apie | T21: Paoadopoulos | U21: Ras
A22: 45676 | B22: Monday | C22: Johnstons | D22: Theron | E22: Paoadopoulos | F22: Apie | H22: Lotz | I22: Klientjie | J22: Bierman | N22: Julia Ann | Q22: Boets
A23: 45677 | B23: Tuesday | C23: Johnstons | D23: Theron | E23: Paoadopoulos | F23: Apie | H23: Lotz | I23: Klientjie | J23: Bierman | O23: Johnstons | Q23: Boets | Y23: Du Plessis
A24: 45678 | B24: Wednesday | D24: Theron | E24: Paoadopoulos | F24: Apie | H24: Lotz | I24: Klientjie | J24: Bierman | O24: Johnstons | Q24: Boets | Y24: Du Plessis
A25: 45679 | B25: Thursday | D25: Theron | E25: Paoadopoulos | F25: Apie | H25: Le Roux | I25: Klientjie | J25: Bierman | O25: Johnstons | T25: Lotz | Y25: Du Plessis
A26: 45680 | B26: Friday | D26: Theron | E26: Paoadopoulos | F26: Apie | H26: Lotz | I26: Klientjie | J26: Bierman | O26: Johnstons | Q26: Boets | Y26: Du Plessis
A27: 45681 | B27: Saturday | E27: Paoadopoulos | F27: Apie | I27: Klientjie | O27: Johnstons
A28: 45682 | B28: Sunday | E28: Paoadopoulos | F28: Apie | I28: Klientjie | O28: Johnstons
A29: 45683 | B29: Monday | C29: Johnstons | D29: Theron | F29: Apie | J29: Bierman | Q29: Boets | T29: Paoadopoulos | U29: Ras | V29: Sui Fon | W29: Klientjie | X29: Barnes | Y29: Du Plessis
A30: 45684 | B30: Tuesday | C30: Johnstons | D30: Theron | F30: Apie | J30: Bierman | Q30: Boets | T30: Paoadopoulos | U30: Ras | W30: Klientjie | X30: Barnes | Y30: Du Plessis
A31: 45685 | B31: Wednesday | C31: Johnstons | D31: Theron | F31: Apie | J31: Bierman | Q31: Boets | T31: Paoadopoulos | U31: Ras | V31: Sui Fon | W31: Klientjie | X31: Barnes | Y31: Du Plessis | Z31: Blumenthal
A32: 45686 | B32: Thursday | C32: Johnstons | D32: Theron | F32: Apie | H32: Le Roux | J32: Bierman | Q32: Boets | T32: Paoadopoulos | U32: Ras | W32: Klientjie | X32: Barnes | Y32: Du Plessis | Z32: Blumenthal
A33: 45687 | B33: Friday | D33: Theron | G33: Scroope | J33: Bierman | M33: Scroope | O33: Johnstons | Q33: Boets | S33: Apie | T33: Paoadopoulos | U33: Ras | V33: Sui Fon | W33: Klientjie | X33: Barnes | Y33: Du Plessis | Z33: Blumenthal
A34: 45688 | B34: Saturday | G34: Scroope | M34: Scroope | O34: Johnstons | S34: Apie | T34: Paoadopoulos | U34: Ras | W34: Klientjie
A35: Days Worked | C35: 16 | D35: 24 | E35: 20 | F35: 19 | G35: 5 | H35: 16 | I35: 21 | J35: 16 | L35: 8 | M35: 11 | N35: 14 | O35: 12 | Q35: 17 | S35: 15 | T35: 14 | U35: 22 | V35: 16 | W35: 8 | X35: 5 | Y35: 9 | Z35: 5
A36: Money added | G36: 800 | J36: 225 | M36: 1250
A37: Money Borrowed | F37: 190 | O37: 50 | Q37: 700 | U37: 809
A38: Total Amount | B38: =SUM(C38:AJ38) | C38: =C2*C35 | D38: =D2*D35 | E38: =E35*E2 | F38: =F35*F2-F37 | G38: =G35*G2+G36 | H38: =H2*H35 | I38: =I2*I35 | J38: =J2*J35+J36 | L38: =L2*L35 | M38: =M2*M35+M36 | N38: =N2*N35 | O38: =O2*O35-O37 | P38: =P2*P35-P37 | Q38: =Q2*Q35-Q37 | R38: =R2*R35 | S38: =S2*S35 | T38: =T2*T35 | U38: =SUM(U2*U35-U37) | V38: =V2*V35-V37 | W38: =W2*W35 | X38: =X2*X35 | Y38: =Y2*Y35 | Z38: =Z2*Z35
B41: Tuniti NPC | C41: =SUM(C38:L38)
B42: TCH | C42: =SUM(M38:Z38)

Sheet Clients Feb 2026
A1: Johnstons- monthly | E1: Van Der Linde- monthly | I1: Rene Lotz/ Wilhelm | M1: John Bierman- monthly | Q1: Wessels | U1: Scroope
A2: Income | E2: Income | I2: Income | M2: Income | Q2: Income | U2: Income
A3: Date: | C3: Payment | E3: Date: | G3: Payment | I3: Date: | K3: Payment | M3: Date: | O3: Payment | Q3: Date: | S3: Payment | U3: Date: | W3: Payment
A4: 46054 | B4: Invoiced NPC | C4: 21000 | E4: 46054 | F4: Invoiced NPC | G4: 22200 | M4: 46054 | N4: Invoiced TCH | O4: 16000 | Q4: 46054 | R4: invoiced | S4: 3800 | U4: 46072 | V4: invoiced | W4: 3350
C8: =SUM(C4:C7) | G8: =SUM(G4:G7) | K8: =SUM(K4:K7) | O8: =SUM(O4:O7) | W8: =SUM(W4:W7)
A9: Expenses | E9: Expenses | I9: Expenses | M9: Expenses | Q9: Expenses | U9: Expenses
A10: Date: | B10: Expense Name | C10: Amount | E10: Date: | F10: Expense Name | G10: Amount | I10: Date: | J10: Expense Name | K10: Amount | M10: Date: | N10: Expense Name | O10: Amount | Q10: Date: | R10: Expense Name | S10: Amount | U10: Date: | V10: Expense Name | W10: Amount
A11: 46054 | B11: Linda | E11: 46054 | F11: Emily | M11: 46054 | N11: Susan | R11: Ruth | V11: Merriam
A12: 46054 | B12: Ada | E12: 46054 | F12: Emma
B13: Sylive | E13: 46054 | F13: Uber
A23: Total Expense | C23: =SUM(C11:C22) | E23: Total Expense | G23: =SUM(G11:G22) | I23: Total Expense | K23: =SUM(K11:K22) | M23: Total Expense | O23: =SUM(O11:O22) | Q23: Total Expense | S23: =SUM(S11:S22) | U23: Total Expense | W23: =SUM(W11:W14)
A24: Income - Expense | C24: =MIN(C4-C23) | E24: Income - Expense | G24: =MIN(G4-G23) | I24: Income - Expense | K24: =MIN(K4-K23) | M24: Income - Expense | O24: =MIN(O4-O23) | Q24: Income - Expense | S24: =MIN(S4-S23) | U24: Income - Expense | W24: =MIN(W8-W23)
A26: Julian Sam | E26: Trevor Botes- monthly | I26: Berthe Botha | M26: Dirk Le Roux- monthly | Q26: Angela/ Dimitri Paoadopoulos- weekly | U26: Du Plessis
A27: Income | E27: Income | I27: Income | M27: Income | Q27: Income | U27: Income
A28: Date: | C28: Payment | E28: Date: | G28: Payment | I28: Date: | K28: Payment | M28: Date: | O28: Payment | Q28: Date: | S28: Payment | U28: Date: | W28: Payment
A29: 46054 | B29: invoiced | C29: 2036 | E29: 45662 | F29: invoiced | G29: 13500 | I29: 46058 | J29: invoiced | K29: 5250 | M29: 46054 | N29: invoiced TCH | O29: 3000 | Q29: 46057 | R29: invoiced | S29: 6650 | U29: 46054 | V29: invoiced | W29: 12500
A30: 46061 | B30: invoiced | C30: 2036 | Q30: 46064 | R30: invoiced | S30: 6650 | U30: 46064 | V30: invoiced | W30: 1500
Q31: 46071 | R31: invoiced | S31: 6650
Q32: 46078 | S32: 6650
C33: =SUM(C29:C32) | G33: =SUM(G29:G32) | K33: =SUM(K29:K32) | O33: =SUM(O29:O32)
A34: Expenses | E34: Expenses | I34: Expenses | M34: Expenses | S34: =SUM(S29:S33) | W34: =SUM(W29:W32)
A35: Date: | B35: Expense Name | C35: Amount | E35: Date: | F35: Expense Name | G35: Amount | I35: Date: | J35: Expense Name | K35: Amount | M35: Date: | N35: Expense Name | O35: Amount | Q35: Expenses | U35: Expenses
A36: 46054 | B36: Siphe | E36: 46054 | F36: Siphilisiwe (Patrica) | I36: 46054 | J36: Emilia | M36: 46054 | N36: Ruth | Q36: Date: | R36: Expense Name | S36: Amount | U36: Date: | V36: Expense Name | W36: Amount
Q37: 45992 | R37: Tracy | U37: 45658 | V37: monique
R38: Musa | V38: Joyce
A48: Total Expense | C48: =SUM(C36:C47) | E48: Total Expense | G48: =SUM(G36:G47) | I48: Total Expense | M48: Total Expense | Q48: Total Expense | U48: Total Expense
A49: Income - Expense | C49: =MIN(C29-C48) | E49: Income - Expense | G49: =MIN(G29-G48) | I49: Income - Expense | M49: Income - Expense | Q49: Income - Expense | U49: Income - Expense
A51: Mia Ras- monthly | E51: Megan Barnes | I51: Johanna Van Heerden- monthly | M51: Andre Theron- monthly | Q51: Derek Halls | U51: Morrison
A52: Income | E52: Income | I52: Income | M52: Income | Q52: Income | U52: Income
A53: Date: | C53: Payment | E53: Date: | G53: Payment | I53: Date: | K53: Payment | M53: Date: | O53: Payment | Q53: Date: | S53: Payment | U53: Date: | W53: Payment
A54: 46054 | B54: invoiced | C54: 11900 | E54: 46054 | F54: invoiced | G54: 13000 | I54: 46054 | J54: Invoiced TCH | K54: 23250 | M54: 46054 | N54: invoiced | O54: 15000 | Q54: 46054 | R54: invoiced | S54: 15000 | U54: 46055 | V54: invoiced
M55: 46070 | N55: invoiced | O55: 3450 | Q55: 46069 | R55: invoiced | S55: 1500 | U55: 46062
U56: 46069
U57: 46076
C59: =SUM(C54:C58) | G59: =SUM(G54:G57) | K59: =SUM(K54:K57) | O59: =SUM(O54:O57) | S59: =SUM(S54:S57) | W59: =SUM(W54:W57)
A60: Expenses | E60: Expenses | I60: Expenses | M60: Expenses | Q60: Expenses | U60: Expenses
A61: Date: | B61: Expense Name | C61: Amount | E61: Date: | F61: Expense Name | G61: Amount | I61: Date: | J61: Expense Name | K61: Amount | M61: Date: | N61: Expense Name | O61: Amount | Q61: Date: | R61: Expense Name | S61: Amount | U61: Date: | V61: Expense Name | W61: Amount
A62: 46054 | B62: Marion | E62: 46023 | F62: Leah | I62: 46054 | J62: Christina | M62: 46054 | N62: Sophia | Q62: 46054 | R62: Busi | U62: 46054
I63: 46054 | J63: Ada | N63: Ndai | R63: Sara
A74: Total Expense | E74: Total Expense | I74: Total Expense | M74: Total Expense | Q74: Total Expense | U74: Total Expense
...

Sheet Caregiver Feb 2026
C1: Linda Rapuluchukwa | D1: Sophie Koga | E1: Joyce Mutambiranwa | F1: Emily Mentula | G1: Cynthia Makondo | H1: Ruth Nnadi | I1: Christina Maluleka | J1: Susan Murire | K1: Ndai Mapenyenye | L1: Adaobi Ejikeme | M1: Merriam Maluleke | N1: Jane Mokgaetsi Moekwa | O1: Sylvia Nene | P1: Matodzi Sylvia Mutavhatsindi | Q1: Siphilisiwe Nkala(Patricia) | R1: Refiloe Khuzwayo | S1: Mmamaswabi Emma Dhlamini | T1: Tracy Nothando Nyirenda | U1: Marion Goeda | V1: Siphethokhuhle Nkomo | W1: Lina Raphahlela | X1: Matshidiso Leah Aphane | Y1: Monique Bosch | Z1: Nhlakanipho (Nipho) Tshabalala | AA1: Musa Zulu | AB1: Busisiwe Mandiyanike | AC1: Emilia Masvosva | AD1: Martha Mashishi | AE1: Sara Mdaka | AF1: Martha Sona | AG1: Julia Ramoroka | AH1: Mbali Ndaba
